<?xml version="1.0"?>
<robot name="kheperas" xmlns:xacro='http://www.ros.org/wiki/xacro'>
	
	<!-- Property List -->
	<xacro:property name='cPi' 		value='3.1415926' 	/> <!-- constant pi -->
	<xacro:property name='pr_base'	value='0.07004' 	/> <!-- dimension parameters of the kheperas body.-->
	<xacro:property name='pl_base'	value='0.053' 		/>
	<xacro:property name='pr_wheel'	value='0.021' 		/> <!-- dimension parameters of the kheperas main wheels. -->
	<xacro:property name='pl_wheel'	value='0.0057'		/>
	<xacro:property name='py_wheel'	value='0.0527'		/>
	<xacro:property name='pz_wheel'	value='0.0102'		/>
	<xacro:property name='pr_caster'	value='0.01134'	/> <!-- dimension parameters of the kheperas casters. -->
	<xacro:property name='px_caster'	value='0.05'		/>
	<xacro:property name='pz_caster'	value='0.01986'	/>
	
	<!-- Color List -->
	<material name='blue'>
		<color rgba='0.0 0.0 1.0 0.6' />
	</material>
	<material	name='white'>
		<color rgba='1.0 1.0 1.0 1.0' />
	</material>
	<material name='black'>
		<color rgba='0.0 0.0 0.0 0.5' />
	</material>
	
	<!-- Macro for robot wheel -->
	<xacro:macro name='wheel' params='prefix reflect'>
		<joint name='$base_{prefix}_wheel_joint'	type='continuous'>
			<origin xyz='0.0 ${reflect*py_wheel} ${-pz_wheel}' rpy='${cPi/2} 0.0 0.0' />
			<parent link='base_link' />
			<child link='${prefix}_wheel_link' />
			<axis xyz='0.0 0.0 0.1' />
		</joint>
		
		<link name='${prefix}_wheel_link'>
			<visual>
				<origin xyz='0.0 0.0 0.0' rpy='0.0 0.0 0.0' />
				<geometry>
					<cylinder radius='${pr_wheel}'	length='${pl_wheel}' />
				</geometry>
				<material name='white' />
			</visual>
		</link>
	</xacro:macro>
	
	<!-- Macro for robot caster -->
	<xacro:macro name='caster' params='prefix reflect'>
		<joint name='${prefix}_caster_joint' type='continuous'>
			<origin xyz='${reflect*px_caster} 0.0 ${-pz_caster}' rpy='0.0 0.0 0.0' />
			<parent link='base_link' />
			<child link='${prefix}_caster_link' />
			<axis xyz='0.0 1.0 0.0' />
		</joint>
		
		<link name='${prefix}_caster_link'>
			<visual>
				<origin xyz='0.0 0.0 0.0' rpy='0.0 0.0 0.0' />
				<geometry>
					<sphere radius='${pr_caster}' />
				</geometry>
				<material name='black' />
			</visual>
		</link>
	</xacro:macro>
	
	<!-- macro for robot base -->
	<xacro:macro name='kheperas'>
		<link name='base_footprint'>
			<visual>
				<origin xyz='0.0 0.0 0.0' rpu='0.0 0.0 0.0' />
				<geometry>
					<box size='0.001 0.001 0.001' />
				</geometry>
			</visual>
		</link>
		
		<joint name='base_footprint_joint' type='fixed'>
			<origin xyz='0.0 0.0 0.0' rpy='0.0 0.0 0.0' />
			<parent link='base_footprint' />
			<child link='base_link' />
		</joint>
		
		<link name='base_link'>
			<visual>
				<origin xyz='0.0 0.0 0.0' rpy='0.0 0.0 0.0' />
				<geometry>
					<cylinder radius='${pr_base}'	length='${pl_base}' />
				</geometry>
				<material name='blue' />
			</visual>
		</link>
		
		<wheel prefix='l' reflect='1' />
		<wheel prefix='r' reflect='-1' />
		
		<caster prefix='front' reflect='1' />
		<caster prefix='back' reflect='-1' />
	</xacro:macro>
</robot>


					
					
					
					
					
					
					
					
					
					
					
					
					
					
					
					
					
					
					
					
					
					
					
					
					
